<?xml version="1.0"?>
<robot name="wheelchair" xmlns:xacro="http://www.ros.org/wiki/xacro">

  <!-- Base Link -->
  <link name="base_link">
    <visual>
      <geometry>
        <box size="0.8 0.6 0.3"/>
      </geometry>
      <material>
        <color rgba="0.5 0.5 0.5 1.0"/> <!-- Gray color -->
      </material>
    </visual>
    <collision>
      <geometry>
        <box size="0.8 0.6 0.3"/>
      </geometry>
    </collision>
  </link>

  <!-- Front Left Wheel -->
  <link name="front_left_wheel">
    <visual>
      <geometry>
        <cylinder radius="0.15" length="0.05"/>
      </geometry>
      <material>
        <color rgba="0 0 0 1.0"/> <!-- Black color -->
      </material>
    </visual>
  </link>

  <!-- Front Right Wheel -->
  <link name="front_right_wheel">
    <visual>
      <geometry>
        <cylinder radius="0.15" length="0.05"/>
      </geometry>
      <material>
        <color rgba="0 0 0 1.0"/> <!-- Black color -->
      </material>
    </visual>
  </link>

  <!-- Joints -->
  <joint name="front_left_wheel_joint" type="continuous">
    <parent link="base_link"/>
    <child link="front_left_wheel"/>
    <origin xyz="0.4 0.3 0.15"/>
    <axis xyz="0 0 1"/>
  </joint>

  <joint name="front_right_wheel_joint" type="continuous">
    <parent link="base_link"/>
    <child link="front_right_wheel"/>
    <origin xyz="0.4 -0.3 0.15"/>
    <axis xyz="0 0 1"/>
  </joint>

</robot>